<mujoco model="gen3_robotiq_2f_85">
  <compiler angle="radian" meshdir="meshes/mujoco_meshes" autolimits="true"/>
  <default>
    <default class="size3">
      <joint armature="0.1" damping="200"/>
      <position kp="3500" forcerange="-150 150"/>
      <default class="size3_limited">
      <!-- NOTE(Mandi): temp change 3.1415 into 2.1415 -->
        <joint range="-3.1415 2.1415"/> 
        <position ctrlrange="-3.1415 2.1415"/>
      </default>
    </default>
    <default class="size1">
      <joint armature="0.1" damping="15"/>
      <position kp="3000" forcerange="-28 28"/>
    </default>
  </default>
  <asset>
    <mesh name="mobile_base" file="mobile_base.obj"/>
    <mesh name="base_link" file="base_link.STL"/>
    <mesh name="shoulder_link" file="shoulder_link.STL"/>
    <mesh name="half_arm_1_link" file="half_arm_1_link.STL"/>
    <mesh name="half_arm_2_link" file="half_arm_2_link.STL"/>
    <mesh name="forearm_link" file="forearm_link.STL"/>
    <mesh name="spherical_wrist_1_link" file="spherical_wrist_1_link.STL"/>
    <mesh name="spherical_wrist_2_link" file="spherical_wrist_2_link.STL"/>
    <mesh name="bracelet_with_vision_link" file="bracelet_with_vision_link.STL"/>
    <mesh name="robotiq_arg2f_base_link_kinova_frame" file="robotiq_arg2f_base_link_kinova_frame.stl"/>
    <mesh name="robotiq_arg2f_85_outer_knuckle" file="robotiq_arg2f_85_outer_knuckle.stl" scale="0.001 0.001 0.001"/>
    <mesh name="robotiq_arg2f_85_outer_finger" file="robotiq_arg2f_85_outer_finger.stl" scale="0.001 0.001 0.001"/>
    <mesh name="robotiq_arg2f_85_inner_finger" file="robotiq_arg2f_85_inner_finger.stl" scale="0.001 0.001 0.001"/>
    <mesh name="robotiq_arg2f_85_pad" file="robotiq_arg2f_85_pad.stl" scale="0.001 0.001 0.001"/>
    <mesh name="robotiq_arg2f_85_inner_knuckle" file="robotiq_arg2f_85_inner_knuckle.stl" scale="0.001 0.001 0.001"/>
  </asset>
  <worldbody>
  <body name="mobile_base" pos="0 0 0.1" quat="0 0 0 1">
    <joint name="base_joint" type="slide" pos="0 0 0" axis="1 0 0" limited="false"/>
    <geom name="mobile_base_visual" type="mesh" contype="0" conaffinity="0" group="1" density="0" rgba="1 1 1 1" mesh="mobile_base"/>
    <geom name="mobile_base_collision" type="mesh" rgba="1 1 1 1" mesh="mobile_base"/>
    <geom name="base_link_visual" pos="0 0 0.335" quat="1.32679e-06 0 0 1" type="mesh" contype="0" conaffinity="0" group="1" density="0" rgba="0.75294 0.75294 0.75294 1" mesh="base_link"/>
    <geom name="base_link_collision" pos="0 0 0.335" quat="1.32679e-06 0 0 1" type="mesh" rgba="0.75294 0.75294 0.75294 1" mesh="base_link"/>
    <body name="shoulder_link" pos="0 0 0.49143" quat="-4.87359e-12 1.32679e-06 1 -3.67321e-06">
      <inertial pos="-2.3e-05 -0.010364 -0.07336" quat="0.707051 0.0451246 -0.0453544 0.704263" mass="1.3773" diaginertia="0.00488868 0.00457 0.00135132"/>
      <joint name="joint_1" pos="0 0 0" axis="0 0 1" limited="true" range="-3.14 3.14"/>
      <geom name="shoulder_link_visual" type="mesh" contype="0" conaffinity="0" group="1" density="0" rgba="0.75294 0.75294 0.75294 1" mesh="shoulder_link"/>
      <geom name="shoulder_link_collision" type="mesh" rgba="0.75294 0.75294 0.75294 1" mesh="shoulder_link"/>
      <body name="half_arm_1_link" pos="0 0.005375 -0.12838" quat="0.707105 0.707108 0 0">
        <inertial pos="-4.4e-05 -0.09958 -0.013278" quat="0.482348 0.516286 -0.516862 0.483366" mass="1.1636" diaginertia="0.0113017 0.011088 0.00102532"/>
        <joint name="joint_2" pos="0 0 0" axis="0 0 1" limited="true" range="-6.2832 6.2832"/>
        <geom name="half_arm_1_link_visual" type="mesh" contype="0" conaffinity="0" group="1" density="0" rgba="0.75294 0.75294 0.75294 1" mesh="half_arm_1_link"/>
        <geom name="half_arm_1_link_collision" type="mesh" rgba="0.75294 0.75294 0.75294 1" mesh="half_arm_1_link"/>
        <body name="half_arm_2_link" pos="0 -0.21038 -0.006375" quat="0.707105 -0.707108 0 0">
          <inertial pos="-4.4e-05 -0.006641 -0.117892" quat="0.706144 0.0213722 -0.0209128 0.707437" mass="1.1636" diaginertia="0.0111633 0.010932 0.00100671"/>
          <joint name="joint_3" pos="0 0 0" axis="0 0 1" limited="true" range="-6.2832 6.2832"/>
          <geom name="half_arm_2_link_visual" type="mesh" contype="0" conaffinity="0" group="1" density="0" rgba="0.75294 0.75294 0.75294 1" mesh="half_arm_2_link"/>
          <geom name="half_arm_2_link_collision" type="mesh" rgba="0.75294 0.75294 0.75294 1" mesh="half_arm_2_link"/>
          <body name="forearm_link" pos="0 0.006375 -0.21038" quat="0.707105 0.707108 0 0">
            <inertial pos="-1.8e-05 -0.075478 -0.015006" quat="0.483678 0.515961 -0.515859 0.483455" mass="0.9302" diaginertia="0.00834839 0.008147 0.000598606"/>
            <joint name="joint_4" pos="0 0 0" axis="0 0 1" limited="true" range="-6.2832 6.2832"/>
            <geom name="forearm_link_visual" type="mesh" contype="0" conaffinity="0" group="1" density="0" rgba="0.75294 0.75294 0.75294 1" mesh="forearm_link"/>
            <geom name="forearm_link_collision" type="mesh" rgba="0.75294 0.75294 0.75294 1" mesh="forearm_link"/>
            <body name="spherical_wrist_1_link" pos="0 -0.20843 -0.006375" quat="0.707105 -0.707108 0 0">
              <inertial pos="1e-06 -0.009432 -0.063883" quat="0.703558 0.0707492 -0.0707492 0.703558" mass="0.6781" diaginertia="0.00165901 0.001596 0.000346988"/>
              <joint name="joint_5" pos="0 0 0" axis="0 0 1" limited="true" range="-6.2832 6.2832"/>
              <geom name="spherical_wrist_1_link_visual" type="mesh" contype="0" conaffinity="0" group="1" density="0" rgba="0.75294 0.75294 0.75294 1" mesh="spherical_wrist_1_link"/>
              <geom name="spherical_wrist_1_link_collision" type="mesh" rgba="0.75294 0.75294 0.75294 1" mesh="spherical_wrist_1_link"/>
              <body name="spherical_wrist_2_link" pos="0 0.00017505 -0.10593" quat="0.707105 0.707108 0 0">
                <inertial pos="1e-06 -0.045483 -0.00965" quat="0.44426 0.550121 -0.550121 0.44426" mass="0.6781" diaginertia="0.00170087 0.001641 0.00035013"/>
                <joint name="joint_6" pos="0 0 0" axis="0 0 1" limited="true" range="-6.2832 6.2832"/>
                <geom name="spherical_wrist_2_link_visual" type="mesh" contype="0" conaffinity="0" group="1" density="0" rgba="0.75294 0.75294 0.75294 1" mesh="spherical_wrist_2_link"/>
                <geom name="spherical_wrist_2_link_collision" type="mesh" rgba="0.75294 0.75294 0.75294 1" mesh="spherical_wrist_2_link"/>
                <body name="bracelet_link" pos="0 -0.10593 -0.00017505" quat="0.707105 -0.707108 0 0">
                  <inertial pos="0.000162549 0.00654647 -0.0668326" quat="0.704328 -0.0617526 0.062935 0.704377" mass="0.870849" diaginertia="0.00333533 0.00279813 0.0014319"/>
                  <joint name="joint_7" pos="0 0 0" axis="0 0 1" limited="true" range="-6.2832 6.2832"/>
                  <geom name="bracelet_with_vision_link_visual" type="mesh" contype="0" conaffinity="0" group="1" density="0" rgba="0.75294 0.75294 0.75294 1" mesh="bracelet_with_vision_link"/>
                  <geom name="bracelet_with_vision_link_collision" type="mesh" rgba="0.75294 0.75294 0.75294 1" mesh="bracelet_with_vision_link"/>
                  <geom name="robotiq_arg2f_base_link_kinova_frame_visual" pos="0 0 -0.061525" quat="0 0.707388 -0.706825 0" type="mesh" contype="0" conaffinity="0" group="1" density="0" rgba="0.1 0.1 0.1 1" mesh="robotiq_arg2f_base_link_kinova_frame"/>
                  <geom name="robotiq_arg2f_base_link_kinova_frame_collision" pos="0 0 -0.061525" quat="0 0.707388 -0.706825 0" type="mesh" rgba="0.1 0.1 0.1 1" mesh="robotiq_arg2f_base_link_kinova_frame"/>
                  
                  <geom name="left_outer_knuckle_visual" pos="0.0306011 2.43685e-05 -0.116429" quat="0.242369 -0.663972 -0.664501 0.242562" type="mesh" contype="0" conaffinity="0" group="1" density="0" rgba="0.2 0.2 0.2 1" mesh="robotiq_arg2f_85_outer_knuckle"/>
                  <geom name="left_outer_knuckle_collision" pos="0.0306011 2.43685e-05 -0.116429" quat="0.242369 -0.663972 -0.664501 0.242562" type="mesh" rgba="0.2 0.2 0.2 1" mesh="robotiq_arg2f_85_outer_knuckle"/>
                  <geom name="left_outer_finger_visual" pos="0.0573349 4.56573e-05 -0.133586" quat="0.242369 -0.663972 -0.664501 0.242562" type="mesh" contype="0" conaffinity="0" group="1" density="0" rgba="0.2 0.2 0.2 1" mesh="robotiq_arg2f_85_outer_finger"/>
                  <geom name="left_outer_finger_collision" pos="0.0573349 4.56573e-05 -0.133586" quat="0.242369 -0.663972 -0.664501 0.242562" type="mesh" rgba="0.2 0.2 0.2 1" mesh="robotiq_arg2f_85_outer_finger"/>
                  <geom name="left_inner_finger_visual" pos="0.0316578 2.521e-05 -0.17354" quat="0 -0.706825 -0.707388 0" type="mesh" contype="0" conaffinity="0" group="1" density="0" rgba="0.75294 0.75294 0.75294 1" mesh="robotiq_arg2f_85_inner_finger"/>
                  <geom name="left_inner_finger_collision" pos="0.0316578 2.521e-05 -0.17354" quat="0 -0.706825 -0.707388 0" type="mesh" rgba="0.75294 0.75294 0.75294 1" mesh="robotiq_arg2f_85_inner_finger"/>
                  <geom name="left_inner_finger_pad_visual" pos="0.0316578 2.521e-05 -0.17354" quat="0 -0.706825 -0.707388 0" type="mesh" contype="0" conaffinity="0" group="1" density="0" rgba="0.9 0.9 0.9 1" mesh="robotiq_arg2f_85_pad"/>
                  <geom name="left_inner_finger_pad_collision" pos="0.0316578 2.521e-05 -0.17354" quat="0 -0.706825 -0.707388 0" type="mesh" rgba="0.9 0.9 0.9 1" mesh="robotiq_arg2f_85_pad"/>
                  <geom name="left_inner_knuckle_visual" pos="0.0127 1.01133e-05 -0.122945" quat="0.242369 -0.663972 -0.664501 0.242562" type="mesh" contype="0" conaffinity="0" group="1" density="0" rgba="0.2 0.2 0.2 1" mesh="robotiq_arg2f_85_inner_knuckle"/>
                  <geom name="left_inner_knuckle_collision" pos="0.0127 1.01133e-05 -0.122945" quat="0.242369 -0.663972 -0.664501 0.242562" type="mesh" rgba="0.2 0.2 0.2 1" mesh="robotiq_arg2f_85_inner_knuckle"/>
                  
                  <geom name="right_outer_knuckle_visual" pos="-0.0306011 -2.43685e-05 -0.116429" quat="-0.242562 0.664501 -0.663972 0.242369" type="mesh" contype="0" conaffinity="0" group="1" density="0" rgba="0.2 0.2 0.2 1" mesh="robotiq_arg2f_85_outer_knuckle"/>
                  <geom name="right_outer_knuckle_collision" pos="-0.0306011 -2.43685e-05 -0.116429" quat="-0.242562 0.664501 -0.663972 0.242369" type="mesh" rgba="0.2 0.2 0.2 1" mesh="robotiq_arg2f_85_outer_knuckle"/>
                  <geom name="right_outer_finger_visual" pos="-0.0573349 -4.56573e-05 -0.133586" quat="-0.242562 0.664501 -0.663972 0.242369" type="mesh" contype="0" conaffinity="0" group="1" density="0" rgba="0.2 0.2 0.2 1" mesh="robotiq_arg2f_85_outer_finger"/>
                  <geom name="right_outer_finger_collision" pos="-0.0573349 -4.56573e-05 -0.133586" quat="-0.242562 0.664501 -0.663972 0.242369" type="mesh" rgba="0.2 0.2 0.2 1" mesh="robotiq_arg2f_85_outer_finger"/>
                  <geom name="right_inner_finger_visual" pos="-0.0316578 -2.521e-05 -0.17354" quat="0 0.707388 -0.706825 0" type="mesh" contype="0" conaffinity="0" group="1" density="0" rgba="1 0 0 1" mesh="robotiq_arg2f_85_inner_finger"/>
                  <geom name="right_inner_finger_collision" pos="-0.0316578 -2.521e-05 -0.17354" quat="0 0.707388 -0.706825 0" type="mesh" rgba="1 0 0 1" mesh="robotiq_arg2f_85_inner_finger"/>
                  <geom name="right_inner_finger_pad_visual" pos="-0.0316578 -2.521e-05 -0.17354" quat="0 0.707388 -0.706825 0" type="mesh" contype="0" conaffinity="0" group="1" density="0" rgba="0.9 0.9 0.9 1" mesh="robotiq_arg2f_85_pad"/>
                  <geom name="right_inner_finger_pad_collision" pos="-0.0316578 -2.521e-05 -0.17354" quat="0 0.707388 -0.706825 0" type="mesh" rgba="0.9 0.9 0.9 1" mesh="robotiq_arg2f_85_pad"/>
                  <geom name="right_inner_knuckle_visual" pos="-0.0127 -1.01133e-05 -0.122945" quat="-0.242562 0.664501 -0.663972 0.242369" type="mesh" contype="0" conaffinity="0" group="1" density="0" rgba="0.2 0.2 0.2 1" mesh="robotiq_arg2f_85_inner_knuckle"/>
                  <geom name="right_inner_knuckle_collision" pos="-0.0127 -1.01133e-05 -0.122945" quat="-0.242562 0.664501 -0.663972 0.242369" type="mesh" rgba="0.2 0.2 0.2 1" mesh="robotiq_arg2f_85_inner_knuckle"/>
                </body>
              </body>
            </body>
          </body>
        </body>
      </body>
    </body>
  </body>
  </worldbody>

  <!-- <tendon>
    <fixed name="split">
      <joint joint="finger_joint1" coef="0.5"/>
      <joint joint="finger_joint2" coef="0.5"/>
    </fixed>
  </tendon> -->

  <!-- Actuate all the joints -->
   <actuator>
    <position name="base_actuator" joint="base_joint" ctrllimited="true" kp="1000" ctrlrange="-1.5 1.3"/>
    <position name="actuator_1" joint="joint_1" class="size3" />
    <position name="actuator_2" joint="joint_2" class="size3" />
    <position name="actuator_3" joint="joint_3" class="size3_limited" />
    <position name="actuator_4" joint="joint_4" class="size1" />
    <position name="actuator_5" joint="joint_5" class="size1" />
    <position name="actuator_6" joint="joint_6" class="size1" /> 
    <position name="actuator_7" joint="joint_7" class="size1" /> 
    <!-- <general class="2f85" name="robotiq_fingers_actuator" tendon="2f85_split" forcerange="-5 5"
        ctrlrange="0 255" gainprm="0.3137255 0 0" biasprm="0 -100 -10"/> -->
  </actuator>
</mujoco>
