<mujoco model="doorcabinet">
  <compiler autolimits="true" angle="radian"/>
  <option integrator="implicit"/>
  <visual>
    <global azimuth="120" elevation="-20" offwidth="2000" offheight="2000"/>
    <quality shadowsize="4096"/>
    <headlight ambient="0.10000000000000001 0.10000000000000001 0.10000000000000001" diffuse="0.59999999999999998 0.59999999999999998 0.59999999999999998" specular="0 0 0"/>
    <rgba haze="0.14999999999999999 0.25 0.34999999999999998 1"/>
  </visual>
  <default>
    <default class="/">
      <default class="object_visual">
        <geom type="mesh" contype="0" conaffinity="0" group="1" mass="1.0000000000000001e-05"/>
      </default>
      <default class="object_sites">
        <site type="cylinder" group="3" size="0.0030000000000000001 0.0060000000000000001"/>
      </default>
      <default class="object_collision">
        <geom group="3" rgba="0.80000000000000004 0.80000000000000004 0.80000000000000004 0.90000000000000002" density="500"/>
      </default>
    </default>
    <default class="cabinet/hingecabinet">
      <joint limited="true" armature="0.01" damping="2" frictionloss="2"/>
      <default class="cabinet/hinge_collision">
        <geom type="box" material="cabinet/white-wood"/>
      </default>
    </default>
    <default class="ur5e/">
      <joint axis="0 1 0" range="-6.2831900000000003 6.2831900000000003"/>
      <site group="4" rgba="0.5 0.5 0.5 0.29999999999999999" size="0.001"/>
      <position ctrlrange="-6.2831000000000001 6.2831000000000001"/>
      <default class="ur5e/visual">
        <geom type="mesh" contype="0" conaffinity="0" group="2"/>
      </default>
      <default class="ur5e/collision">
        <geom type="capsule" group="3"/>
        <default class="ur5e/eef_collision">
          <geom type="cylinder"/>
        </default>
      </default>
      <default class="ur5e/size3">
        <joint armature="0.10000000000000001" damping="200"/>
        <position forcerange="-150 150" kp="3500"/>
        <default class="ur5e/size3_limited">
          <joint range="-3.1415000000000002 2.1415000000000002"/>
          <position ctrlrange="-3.1415000000000002 2.1415000000000002"/>
        </default>
      </default>
      <default class="ur5e/size1">
        <joint armature="0.10000000000000001" damping="15"/>
        <position forcerange="-28 28" kp="3000"/>
      </default>
      <default class="ur5e/active_adhesion">
        <geom margin="0.01" gap="0.01"/>
      </default>
      <default class="ur5e/2f85">
        <mesh scale="0.001 0.001 0.001"/>
        <joint axis="1 0 0"/>
        <general biastype="affine"/>
        <default class="ur5e/2f85_driver">
          <joint solreflimit="0.0050000000000000001 1" solimplimit="0.94999999999999996 0.98999999999999999 0.001" range="0 0.80000000000000004" armature="0.0050000000000000001" damping="0.10000000000000001"/>
        </default>
        <default class="ur5e/2f85_follower">
          <joint pos="0 -0.017999999999999999 0.0064999999999999997" solreflimit="0.0050000000000000001 1" solimplimit="0.94999999999999996 0.98999999999999999 0.001" range="-0.872664 0.872664"/>
        </default>
        <default class="ur5e/2f85_spring_link">
          <joint stiffness="0.050000000000000003" range="-0.29670597283 0.80000000000000004" springref="2.6200000000000001" damping="0.00125"/>
        </default>
        <default class="ur5e/2f85_coupler">
          <joint solreflimit="0.0050000000000000001 1" solimplimit="0.94999999999999996 0.98999999999999999 0.001" range="-1.5700000000000001 0"/>
        </default>
        <default class="ur5e/2f85_visual">
          <geom type="mesh" contype="0" conaffinity="0" group="2"/>
        </default>
        <default class="ur5e/2f85_collision">
          <geom type="mesh" group="3"/>
          <default class="ur5e/2f85_pad_box1">
            <geom type="box" priority="1" size="0.010999999999999999 0.0040000000000000001 0.0093749999999999997" rgba="0.55000000000000004 0.55000000000000004 0.55000000000000004 1" friction="0.69999999999999996" mass="0" solref="0.0040000000000000001 1" solimp="0.94999999999999996 0.98999999999999999 0.001" pos="0 -0.0025999999999999999 0.028125000000000001"/>
          </default>
          <default class="ur5e/2f85_pad_box2">
            <geom type="box" priority="1" size="0.010999999999999999 0.0040000000000000001 0.0093749999999999997" rgba="0.45000000000000001 0.45000000000000001 0.45000000000000001 1" friction="0.59999999999999998" mass="0" solref="0.0040000000000000001 1" solimp="0.94999999999999996 0.98999999999999999 0.001" pos="0 -0.0025999999999999999 0.0093749999999999997"/>
          </default>
        </default>
      </default>
    </default>
    <default class="panda2/">
      <default class="panda2/panda">
        <material specular="0.5" shininess="0.25"/>
        <joint axis="0 0 1" range="-2.8973 2.8973" armature="0.10000000000000001" damping="15"/>
        <general ctrlrange="-2.8973 2.8973" forcerange="-87 87" dyntype="none" biastype="affine"/>
        <default class="panda2/finger">
          <joint type="slide" axis="0 1 0" range="0 0.040000000000000001"/>
        </default>
        <default class="panda2/visual">
          <geom type="mesh" contype="0" conaffinity="0" group="2"/>
        </default>
        <default class="panda2/collision">
          <geom type="mesh" group="3"/>
          <default class="panda2/fingertip_pad_collision_1">
            <geom type="box" size="0.0085000000000000006 0.0040000000000000001 0.0085000000000000006" pos="0 0.0054999999999999997 0.044499999999999998"/>
          </default>
          <default class="panda2/fingertip_pad_collision_2">
            <geom type="box" size="0.0030000000000000001 0.002 0.0030000000000000001" pos="0.0054999999999999997 0.002 0.050000000000000003"/>
          </default>
          <default class="panda2/fingertip_pad_collision_3">
            <geom type="box" size="0.0030000000000000001 0.002 0.0030000000000000001" pos="-0.0054999999999999997 0.002 0.050000000000000003"/>
          </default>
          <default class="panda2/fingertip_pad_collision_4">
            <geom type="box" size="0.0030000000000000001 0.002 0.0035000000000000001" pos="0.0054999999999999997 0.002 0.0395"/>
          </default>
          <default class="panda2/fingertip_pad_collision_5">
            <geom type="box" size="0.0030000000000000001 0.002 0.0035000000000000001" pos="-0.0054999999999999997 0.002 0.0395"/>
          </default>
        </default>
      </default>
    </default>
  </default>
  <asset>
    <texture name="groundplane" type="2d" builtin="checker" rgb1="0.20000000000000001 0.29999999999999999 0.40000000000000002" rgb2="0.10000000000000001 0.20000000000000001 0.29999999999999999" mark="edge" markrgb="0.80000000000000004 0.80000000000000004 0.80000000000000004" width="300" height="300"/>
    <material name="groundplane" class="/" texture="groundplane" texrepeat="2 2" texuniform="true" reflectance="0.20000000000000001"/>
    <texture name="cabinet/tex-white-wood" type="2d" file="white-wood-64e46996d82e79fc2c74726c632744b87ff20496.png"/>
    <material name="cabinet/white-wood" class="cabinet/hingecabinet" texture="cabinet/tex-white-wood" texrepeat="15 15" texuniform="true" reflectance="0.59999999999999998"/>
    <material name="cabinet/quiet-black" class="cabinet/hingecabinet" shininess="0.20000000000000001" reflectance="0.20000000000000001" rgba="0.14999999999999999 0.14999999999999999 0.14999999999999999 1"/>
    <material name="ur5e/black" class="ur5e/" specular="0.5" shininess="0.25" rgba="0.033000000000000002 0.033000000000000002 0.033000000000000002 1"/>
    <material name="ur5e/jointgray" class="ur5e/" specular="0.5" shininess="0.25" rgba="0.27800000000000002 0.27800000000000002 0.27800000000000002 1"/>
    <material name="ur5e/linkgray" class="ur5e/" specular="0.5" shininess="0.25" rgba="0.81999999999999995 0.81999999999999995 0.81999999999999995 1"/>
    <material name="ur5e/urblue" class="ur5e/" specular="0.5" shininess="0.25" rgba="0.48999999999999999 0.67800000000000005 0.80000000000000004 1"/>
    <mesh name="ur5e/base_0" class="ur5e/" file="base_0-01ac9e021b318b0e7d68ff459355d312632dbce2.obj"/>
    <mesh name="ur5e/base_1" class="ur5e/" file="base_1-da27aa91c3acaba915e69da82940923e8501c8de.obj"/>
    <mesh name="ur5e/shoulder_0" class="ur5e/" file="shoulder_0-bf7855fd010d1c54a98a11f60b3afad8bd4aadfe.obj"/>
    <mesh name="ur5e/shoulder_1" class="ur5e/" file="shoulder_1-7d0cc0130030e332d93536db5491a18c2bf9a684.obj"/>
    <mesh name="ur5e/shoulder_2" class="ur5e/" file="shoulder_2-a88161eebf91e6f5ea9026af10a9711c890c43ca.obj"/>
    <mesh name="ur5e/upperarm_0" class="ur5e/" file="upperarm_0-0814fd52ab16b56d9f667bda15adb6f7a9d54085.obj"/>
    <mesh name="ur5e/upperarm_1" class="ur5e/" file="upperarm_1-3aa0a436ac9e0f69baeaad7e0d1946f3d7ff56d4.obj"/>
    <mesh name="ur5e/upperarm_2" class="ur5e/" file="upperarm_2-9c447cfe9d00d0a517e31c6e74c89a8d4830f238.obj"/>
    <mesh name="ur5e/upperarm_3" class="ur5e/" file="upperarm_3-57fca7bb6fe1dd15fc9ea9a60127129fb223e719.obj"/>
    <mesh name="ur5e/forearm_0" class="ur5e/" file="forearm_0-518a987cde744a0e060696f44024d6aa78c51051.obj"/>
    <mesh name="ur5e/forearm_1" class="ur5e/" file="forearm_1-718f4f65473e9d0e5fe40654f3db5b0af2a9cf77.obj"/>
    <mesh name="ur5e/forearm_2" class="ur5e/" file="forearm_2-8dd7b551ebafbbda1af34277052cf9c5f9c2b88e.obj"/>
    <mesh name="ur5e/forearm_3" class="ur5e/" file="forearm_3-4f28dd6924877564f972726f6dbb9660ddb3f5a6.obj"/>
    <mesh name="ur5e/wrist1_0" class="ur5e/" file="wrist1_0-eb4a67397a95e9fad0b558c70c7c085756686e19.obj"/>
    <mesh name="ur5e/wrist1_1" class="ur5e/" file="wrist1_1-0a91e6e5738404efeb7baf8c40ca863181684777.obj"/>
    <mesh name="ur5e/wrist1_2" class="ur5e/" file="wrist1_2-6be153607122936c166bbb8749fc8bc9c163c1cf.obj"/>
    <mesh name="ur5e/wrist2_0" class="ur5e/" file="wrist2_0-0d7828c1862809a81b22547f39d7737343b884df.obj"/>
    <mesh name="ur5e/wrist2_1" class="ur5e/" file="wrist2_1-df89f78f553e0109cb8445c23880d84d1be4b3f6.obj"/>
    <mesh name="ur5e/wrist2_2" class="ur5e/" file="wrist2_2-889836a3f9d09370036992adda20050d49fd9b15.obj"/>
    <mesh name="ur5e/wrist3" class="ur5e/" file="wrist3-019452ce9e64e8d1405c28c1f689e388edfe7559.obj"/>
    <mesh name="ur5e/suction_base_mesh" class="ur5e/" file="base-65b1beaf2b1b0ad2da03f21f7ef4c567b9e8ddf9.obj" scale="0.001 0.001 0.001"/>
    <mesh name="ur5e/suction_mid_mesh" class="ur5e/" file="mid_suction-250afaf50ff4cb3f1386c05b10142358ec7f2663.obj" scale="0.001 0.001 0.001"/>
    <mesh name="ur5e/suction_head_mesh" class="ur5e/" file="head-ab254ef4c26191a23d6145e1c6ace3872ba0ba07.obj" scale="0.0015 0.0015 0.0015"/>
    <mesh name="ur5e/suction_tip_mesh" class="ur5e/" file="tip-4bebfa5848bbe8aad73e89966f9e6793af2d0513.obj" scale="0.0015 0.0015 0.0015"/>
    <material name="ur5e/DarkGrey" class="ur5e/" rgba="0.20000000000000001 0.20000000000000001 0.20000000000000001 1"/>
    <material name="ur5e/suction_blue" class="ur5e/" rgba="0.18039216 0.50588235000000004 0.77254902000000003 1"/>
    <material name="ur5e/metal" class="ur5e/" rgba="0.57999999999999996 0.57999999999999996 0.57999999999999996 1"/>
    <material name="ur5e/silicone" class="ur5e/" rgba="0.18820000000000001 0.18820000000000001 0.18820000000000001 1"/>
    <material name="ur5e/gray" class="ur5e/" rgba="0.4627 0.4627 0.4627 1"/>
    <material name="ur5e/2f85_black" class="ur5e/" rgba="0.14899999999999999 0.14899999999999999 0.14899999999999999 1"/>
    <mesh name="ur5e/base_mount" class="ur5e/2f85" file="base_mount-22e57178defe77afb6bdd333bfae16607f1eb3dd.stl"/>
    <mesh name="ur5e/base" class="ur5e/2f85" file="base-e5dacbcc3971bfdb549ff8c7d38ea873ca7f2933.stl"/>
    <mesh name="ur5e/driver" class="ur5e/2f85" file="driver-97efa43184c575b31ff1f3980641896f51492762.stl"/>
    <mesh name="ur5e/coupler" class="ur5e/2f85" file="coupler-0a4240dc94992944cca6ec9e270ff1658fa86c55.stl"/>
    <mesh name="ur5e/follower" class="ur5e/2f85" file="follower-39e4b8048f1395ee38cb45b37b5fec0e6f2aaec9.stl"/>
    <mesh name="ur5e/pad" class="ur5e/2f85" file="pad-e6a633b2c81740b1f783ec4c6e695c8cc570f09d.stl"/>
    <mesh name="ur5e/silicone_pad" class="ur5e/2f85" file="silicone_pad-c284384f3ca6dcdc24d6188a5d1a2d4c42c412ac.stl"/>
    <mesh name="ur5e/spring_link" class="ur5e/2f85" file="spring_link-8f50234325193b84e9f86b7a63a24560a389c9bf.stl"/>
    <material name="panda2/white" class="panda2/panda" rgba="1 1 1 1"/>
    <material name="panda2/off_white" class="panda2/panda" rgba="0.90196100000000001 0.92156899999999997 0.92941200000000002 1"/>
    <material name="panda2/black" class="panda2/panda" rgba="0.25 0.25 0.25 1"/>
    <material name="panda2/green" class="panda2/panda" rgba="0 1 0 1"/>
    <material name="panda2/light_blue" class="panda2/panda" rgba="0.039216000000000001 0.54117599999999999 0.78039199999999997 1"/>
    <mesh name="panda2/link0_c" class="panda2/" file="link0-3f633d19409870795516c6de40b4c7922f53c43d.stl"/>
    <mesh name="panda2/link1_c" class="panda2/" file="link1-53f934209b6019b996b6d9c714d0a9cf102f7fb2.stl"/>
    <mesh name="panda2/link2_c" class="panda2/" file="link2-8500c695b73e8ceeaa520c02db5684f02793b80f.stl"/>
    <mesh name="panda2/link3_c" class="panda2/" file="link3-0af960563df21dd3a3b0afac6e34f62bf10c71c4.stl"/>
    <mesh name="panda2/link4_c" class="panda2/" file="link4-97c9a53ee35f3939b3438a38005e78fd4c9f23cb.stl"/>
    <mesh name="panda2/link5_c0" class="panda2/" file="link5_collision_0-f402b8885893e833c27f7eca01b669b81476a48f.obj"/>
    <mesh name="panda2/link5_c1" class="panda2/" file="link5_collision_1-3735bde5d4211e2d565b9cc20b919f55e697be05.obj"/>
    <mesh name="panda2/link5_c2" class="panda2/" file="link5_collision_2-585e84d1d7e381827b73c7ecd50f2010775235c9.obj"/>
    <mesh name="panda2/link6_c" class="panda2/" file="link6-e9fa3ad660cf2a9b04e0ec55e8d56abf5891d531.stl"/>
    <mesh name="panda2/link7_c" class="panda2/" file="link7-5dcc7199c8e231447ebda37651ead64ebe3cf6ec.stl"/>
    <mesh name="panda2/hand_c" class="panda2/" file="hand-56394d6e04b1579484cd4323dc50c3240332cfe2.stl"/>
    <mesh name="panda2/link0_0" class="panda2/" file="link0_0-b7cf6e228cebc1309b79491310541fe8a60e2d62.obj"/>
    <mesh name="panda2/link0_1" class="panda2/" file="link0_1-5ecc0c585f0d6a4207ba87f6aeed2df5632b2ebe.obj"/>
    <mesh name="panda2/link0_2" class="panda2/" file="link0_2-88529048e478fb7cca6eeeaaa0405b00ca337c0a.obj"/>
    <mesh name="panda2/link0_3" class="panda2/" file="link0_3-75c03dfe4002c399dfeaea609db33c25ae42f82f.obj"/>
    <mesh name="panda2/link0_4" class="panda2/" file="link0_4-6917a10a52309fc722169515f143ac9bd6a2b084.obj"/>
    <mesh name="panda2/link0_5" class="panda2/" file="link0_5-8d54ecd0c38e0b412ac31ef46675fdca7e0e4717.obj"/>
    <mesh name="panda2/link0_7" class="panda2/" file="link0_7-79cbcc01643937964f9e547e9b3d225888aa50c7.obj"/>
    <mesh name="panda2/link0_8" class="panda2/" file="link0_8-4c89da97ea30fff7777d1a961c922a48425291ef.obj"/>
    <mesh name="panda2/link0_9" class="panda2/" file="link0_9-776b30016c2bb8f206d560786910bfccb809926d.obj"/>
    <mesh name="panda2/link0_10" class="panda2/" file="link0_10-d7b529ebc6940c0415ad91e938b0c39f05853d07.obj"/>
    <mesh name="panda2/link0_11" class="panda2/" file="link0_11-46418d08940dd95e72b8290253d6bfb37aa3ba10.obj"/>
    <mesh name="panda2/link1" class="panda2/" file="link1-ed231c089447a0928504d8a0b6d31c196f6f4b28.obj"/>
    <mesh name="panda2/link2" class="panda2/" file="link2-21fdd1eb16bc9d11a5349b39cc21c9ecafff6cb2.obj"/>
    <mesh name="panda2/link3_0" class="panda2/" file="link3_0-644740d89be54fee424dac34a096ed07f0c0be9a.obj"/>
    <mesh name="panda2/link3_1" class="panda2/" file="link3_1-aa5980b7ffb0ff37d6f81bf5d03cca87b4182c72.obj"/>
    <mesh name="panda2/link3_2" class="panda2/" file="link3_2-41efc81a33bb7585a8676c163e2d66ac5cc1fbb5.obj"/>
    <mesh name="panda2/link3_3" class="panda2/" file="link3_3-c433c61f6a518e2810fa405a084aa55ae95bc09c.obj"/>
    <mesh name="panda2/link4_0" class="panda2/" file="link4_0-70b359cb835f79b58037732ffb174c30589ca379.obj"/>
    <mesh name="panda2/link4_1" class="panda2/" file="link4_1-8a206f8e5eee869db6b4d9e77db083f6edbc5e6b.obj"/>
    <mesh name="panda2/link4_2" class="panda2/" file="link4_2-5c5b38db50c3864953a5ee4766d35f5fae84e0dc.obj"/>
    <mesh name="panda2/link4_3" class="panda2/" file="link4_3-46cdfe6cf343836b30218551cd40c45197cd3f7d.obj"/>
    <mesh name="panda2/link5_0" class="panda2/" file="link5_0-c9c057e806e8a7919fb33f70114229b6d3c40dcd.obj"/>
    <mesh name="panda2/link5_1" class="panda2/" file="link5_1-f07ba3f01e7be86042be33cef54249a02bd73749.obj"/>
    <mesh name="panda2/link5_2" class="panda2/" file="link5_2-fc227a4bf91b7bc23a55448c810557f391f1d5e3.obj"/>
    <mesh name="panda2/link6_0" class="panda2/" file="link6_0-6836f8b697cf67e536dc9bbd5fa9250c58c12ca7.obj"/>
    <mesh name="panda2/link6_1" class="panda2/" file="link6_1-d0da79111a0c81081fcdfa01fb58586c92d8322d.obj"/>
    <mesh name="panda2/link6_2" class="panda2/" file="link6_2-d6b659cb277c78c300d62cdb6449eaaa8814b5d2.obj"/>
    <mesh name="panda2/link6_3" class="panda2/" file="link6_3-ba09733138cd64d0a7366ffe1385267da3597481.obj"/>
    <mesh name="panda2/link6_4" class="panda2/" file="link6_4-32e7cb101a33786176152037acd0a8872e7d5ad5.obj"/>
    <mesh name="panda2/link6_5" class="panda2/" file="link6_5-38d0c1ecd191ee8d914ba6b7a6afa271432c665f.obj"/>
    <mesh name="panda2/link6_6" class="panda2/" file="link6_6-5ed9d943e4d2c63735b56d3e3635a3a07c6470db.obj"/>
    <mesh name="panda2/link6_7" class="panda2/" file="link6_7-106080e92cb497bc3906f4e5ee2f49fd62ea7f89.obj"/>
    <mesh name="panda2/link6_8" class="panda2/" file="link6_8-bbfe67149c4cfd9d81968a91844069d474f53f2d.obj"/>
    <mesh name="panda2/link6_9" class="panda2/" file="link6_9-09876ce72bf2f306c3ac7005f461a2d88f78dccd.obj"/>
    <mesh name="panda2/link6_10" class="panda2/" file="link6_10-b0430678bf45d2dcb5a064b8a19f1f93945864fb.obj"/>
    <mesh name="panda2/link6_11" class="panda2/" file="link6_11-dbcbe820a516782674773335ffc26931de719df1.obj"/>
    <mesh name="panda2/link6_12" class="panda2/" file="link6_12-7f56f8ec4561cb5b724ff00e00d6f0efe8bf7123.obj"/>
    <mesh name="panda2/link6_13" class="panda2/" file="link6_13-a0d4d39ca68ff2ec5a17977ecc13dc02b5b4fdd2.obj"/>
    <mesh name="panda2/link6_14" class="panda2/" file="link6_14-fde4741db758169025860d9d06157c80aab9f9c0.obj"/>
    <mesh name="panda2/link6_15" class="panda2/" file="link6_15-5e7addd48c4088cfeb5280ef77bc69e4cdb45939.obj"/>
    <mesh name="panda2/link6_16" class="panda2/" file="link6_16-d583372e8c9632ad1aa003ef6c5ac09effbf2102.obj"/>
    <mesh name="panda2/link7_0" class="panda2/" file="link7_0-2e4ca001c5c670d1e7b84e342df95cc1b01ee137.obj"/>
    <mesh name="panda2/link7_1" class="panda2/" file="link7_1-3dfe858021e5f7d422c2f51e5663f07272b758fc.obj"/>
    <mesh name="panda2/link7_2" class="panda2/" file="link7_2-2643e68c73e2988b9f66992bdd9ea846cae1e128.obj"/>
    <mesh name="panda2/link7_3" class="panda2/" file="link7_3-9eff475605fd7c4d72ff0031ee375b7bab95920b.obj"/>
    <mesh name="panda2/link7_4" class="panda2/" file="link7_4-6ea88c0c0f5a79079aa03008291a9df01ea43ed5.obj"/>
    <mesh name="panda2/link7_5" class="panda2/" file="link7_5-916ac62d00e858d819cb553fe73db314185cdd47.obj"/>
    <mesh name="panda2/link7_6" class="panda2/" file="link7_6-9d637adbf9ceabb0d5f85515c03d065c54fde3dc.obj"/>
    <mesh name="panda2/link7_7" class="panda2/" file="link7_7-652eee34bbafccbee18e5c1c8f96823fcaaf242d.obj"/>
    <mesh name="panda2/hand_0" class="panda2/" file="hand_0-cfe318371d80d790934fba8bf6b6fb7f64071ac6.obj"/>
    <mesh name="panda2/hand_1" class="panda2/" file="hand_1-7cd93918f5bc964665658b0af0ff92876fe9a85d.obj"/>
    <mesh name="panda2/hand_2" class="panda2/" file="hand_2-9aff904f0b08a77437e7894da1d4efc4d4a52059.obj"/>
    <mesh name="panda2/hand_3" class="panda2/" file="hand_3-9909795ec9ec03e824cbb49691c32a4366fb2f4d.obj"/>
    <mesh name="panda2/hand_4" class="panda2/" file="hand_4-8a7602e34e1ed3ddacdaa10cf857f811276d4a2c.obj"/>
    <mesh name="panda2/finger_0" class="panda2/" file="finger_0-cf20576acd5b52daef643d398ae3b30fee1027d3.obj"/>
    <mesh name="panda2/finger_1" class="panda2/" file="finger_1-87276f8cb602e3141fccda3eb9b263c18fba3fe1.obj"/>
  </asset>
  <worldbody>
    <light name="//unnamed_light_0" class="/" directional="true" pos="0 0 1.5" dir="0 0 -1"/>
    <geom name="floor" class="/" type="plane" size="0 0 0.050000000000000003" material="groundplane" pos="0 0 -0.5"/>
    <body name="table" pos="0 0.5 0">
      <geom name="table_collision" class="/" type="box" size="1.6000000000000001 0.5 0.050000000000000003" pos="0 0 0.10000000000000001"/>
      <body name="table_top" pos="0 0 0.11">
        <geom name="table_top" class="/" type="box" contype="0" conaffinity="0" group="1" size="1.6000000000000001 0.40000000000000002 0.050000000000000003"/>
      </body>
      <geom name="table_left" class="/" type="box" size="0.02 1.6000000000000001 1.5" rgba="1 1 1 0" pos="-1.6299999999999999 0 1"/>
      <geom name="table_right" class="/" type="box" size="0.02 1.6000000000000001 1.5" rgba="1 1 1 0" pos="1.6299999999999999 0 1"/>
      <geom name="table_front" class="/" type="box" size="1.7 0.02 1.5" rgba="1 1 1 0" pos="0 1.6299999999999999 1"/>
      <geom name="table_back" class="/" type="box" size="1.7 0.02 1.5" rgba="1 1 1 0" pos="0 -1.6299999999999999 1"/>
    </body>
    <body name="keycard" pos="0.5 0.59999999999999998 0.10000000000000001">
      <freejoint name="keycard_joint"/>
      <geom name="keycard" class="/" type="box" size="0.050000000000000003 0.10000000000000001 0.01" rgba="0 0 0 1"/>
    </body>
    <body name="cabinet/">
      <body name="cabinet/cabinet" pos="-0.69999999999999996 0.5 0.5" quat="0.70699999999999996 0 0 0.70699999999999996">
        <body name="cabinet/cabinet_body" pos="0 0 0.10000000000000001">
          <geom name="cabinet/cabinet_right" class="cabinet/hinge_collision" type="box" size="0.01 0.20000000000000001 0.59999999999999998" mass="0.20000000000000001" pos="0.34000000000000002 0 0"/>
          <geom name="cabinet/cabinet_left" class="cabinet/hinge_collision" type="box" size="0.01 0.20000000000000001 0.59999999999999998" mass="0.20000000000000001" pos="-0.34000000000000002 0 0"/>
          <geom name="cabinet/cabinet_top" class="cabinet/hinge_collision" type="box" size="0.34999999999999998 0.20000000000000001 0.029999999999999999" mass="0.20000000000000001" pos="0 0 0.29999999999999999"/>
          <geom name="cabinet/cabinet_bottom" class="cabinet/hinge_collision" type="box" size="0.34999999999999998 0.20000000000000001 0.029999999999999999" mass="0.20000000000000001" pos="0 0 -0.29999999999999999"/>
          <geom name="cabinet/cabinet_back" class="cabinet/hinge_collision" type="box" size="0.33000000000000002 0.014999999999999999 0.29999999999999999" mass="0.20000000000000001" pos="0 0.19 0"/>
          <geom name="cabinet/cabinet_panel" class="cabinet/hinge_collision" type="box" size="0.33000000000000002 0.20000000000000001 0.029999999999999999" mass="0.20000000000000001" pos="0 0 0"/>
          <body name="cabinet/cabinet_leftdoor" pos="-0.34000000000000002 -0.20000000000000001 0">
            <geom name="cabinet/leftdoor" class="cabinet/hinge_collision" type="box" size="0.16 0.014999999999999999 0.59999999999999998" mass="3" pos="0.17000000000000001 -0.02 0"/>
            <body name="cabinet/key-reader" pos="0 0 0">
              <geom name="cabinet/keyreader" class="cabinet/hingecabinet" type="box" size="0.080000000000000002 0.014999999999999999 0.10000000000000001" material="cabinet/quiet-black" mass="3" pos="0.17000000000000001 -0.050000000000000003 0.20000000000000001"/>
            </body>
          </body>
          <body name="cabinet/cabinet_rightdoor" pos="0.34000000000000002 -0.20000000000000001 0">
            <joint name="cabinet/rightdoorhinge" class="cabinet/hingecabinet" axis="0 0 1" range="0 2.6000000000000001" damping="100"/>
            <inertial pos="-0.029999999999999999 -0.02 0" mass="0.59999999999999998" diaginertia="0.01 0.01 0.01"/>
            <geom name="cabinet/rightdoor" class="cabinet/hinge_collision" type="box" size="0.16 0.014999999999999999 0.59999999999999998" mass="3" pos="-0.17000000000000001 -0.02 0"/>
            <geom name="cabinet/righthandle" class="cabinet/hinge_collision" type="cylinder" size="0.014999999999999999 0.40000000000000002" material="cabinet/quiet-black" mass="0.20000000000000001" pos="-0.23000000000000001 -0.080000000000000002 0.14999999999999999"/>
            <geom name="cabinet/righthandle_top" class="cabinet/hinge_collision" type="cylinder" size="0.012999999999999999 0.02 0.02" material="cabinet/quiet-black" mass="0.02" pos="-0.23000000000000001 -0.060999999999999999 0.080000000000000002" euler="1.5700000000000001 0 0"/>
            <geom name="cabinet/righthandle_bottom" class="cabinet/hinge_collision" type="cylinder" size="0.012999999999999999 0.02 0.02" material="cabinet/quiet-black" mass="0.02" pos="-0.23000000000000001 -0.060999999999999999 -0.080000000000000002" euler="1.5700000000000001 0 0"/>
            <site name="cabinet/cabinet_rdoor" class="cabinet/hingecabinet" type="sphere" group="3" rgba="0 1 0 1" size="0.02" pos="-0.23000000000000001 -0.13 0" euler="1.5700000000000001 0 1.5700000000000001"/>
            <body name="cabinet/right_door_handle" pos="-0.23000000000000001 -0.10000000000000001 0" euler="1.5700000000000001 0 1.5700000000000001"/>
            <site name="cabinet/right_door_handle" class="cabinet/hingecabinet" group="3" pos="-0.23000000000000001 -0.10000000000000001 0" euler="1.5700000000000001 0 1.5700000000000001"/>
          </body>
        </body>
      </body>
    </body>
    <camera name="my_camera" class="/" pos="2.1000000000000001 -0.14999999999999999 1.7310000000000001" xyaxes="0.48699999999999999 0.874 0 -0.5 0.27800000000000002 0.81999999999999995"/>
    <site name="ur5e" class="/" size="0.001 0.001 0.001" pos="0.20000000000000001 1.2 0.10000000000000001"/>
    <body pos="0.20000000000000001 1.2 0.10000000000000001" name="ur5e/">
      <body name="ur5e/ur5e_0_base" quat="1 0 0 0">
        <joint name="ur5e/ur5e_0_base_joint" class="ur5e/" type="slide" axis="1 0 0" range="-1.3 1.3" armature="1" damping="1000"/>
        <inertial pos="0 0 0" mass="4" diaginertia="0.0044333315599999999 0.0044333315599999999 0.0071999999999999998"/>
        <geom name="ur5e//unnamed_geom_0" class="ur5e/visual" material="ur5e/black" mesh="ur5e/base_0"/>
        <geom name="ur5e//unnamed_geom_1" class="ur5e/visual" material="ur5e/jointgray" mesh="ur5e/base_1"/>
        <body name="ur5e/ur5e_0_shoulder_link" pos="0 0 0.16300000000000001">
          <inertial pos="0 0 0" mass="3.7000000000000002" diaginertia="0.010267500000000001 0.010267500000000001 0.0066600000000000001"/>
          <joint name="ur5e/ur5e_0_shoulder_pan_joint" class="ur5e/size3" axis="0 0 1"/>
          <geom name="ur5e//unnamed_geom_2" class="ur5e/visual" material="ur5e/urblue" mesh="ur5e/shoulder_0"/>
          <geom name="ur5e//unnamed_geom_3" class="ur5e/visual" material="ur5e/black" mesh="ur5e/shoulder_1"/>
          <geom name="ur5e//unnamed_geom_4" class="ur5e/visual" material="ur5e/jointgray" mesh="ur5e/shoulder_2"/>
          <geom name="ur5e//unnamed_geom_5" class="ur5e/collision" size="0.059999999999999998 0.059999999999999998" pos="0 0 -0.040000000000000001"/>
          <body name="ur5e/ur5e_0_upper_arm_link" pos="0 0.13800000000000001 0" quat="1 0 1 0">
            <inertial pos="0 0 0.21249999999999999" mass="8.3930000000000007" diaginertia="0.13388600000000001 0.13388600000000001 0.0151074"/>
            <joint name="ur5e/ur5e_0_shoulder_lift_joint" class="ur5e/size3"/>
            <geom name="ur5e//unnamed_geom_6" class="ur5e/visual" material="ur5e/linkgray" mesh="ur5e/upperarm_0"/>
            <geom name="ur5e//unnamed_geom_7" class="ur5e/visual" material="ur5e/black" mesh="ur5e/upperarm_1"/>
            <geom name="ur5e//unnamed_geom_8" class="ur5e/visual" material="ur5e/jointgray" mesh="ur5e/upperarm_2"/>
            <geom name="ur5e//unnamed_geom_9" class="ur5e/visual" material="ur5e/urblue" mesh="ur5e/upperarm_3"/>
            <geom name="ur5e//unnamed_geom_10" class="ur5e/collision" size="0.059999999999999998 0.059999999999999998" pos="0 -0.040000000000000001 0" quat="1 1 0 0"/>
            <geom name="ur5e//unnamed_geom_11" class="ur5e/collision" size="0.050000000000000003 0.20000000000000001" pos="0 0 0.20000000000000001"/>
            <body name="ur5e/ur5e_0_forearm_link" pos="0 -0.13100000000000001 0.42499999999999999">
              <inertial pos="0 0 0.19600000000000001" mass="2.2749999999999999" diaginertia="0.031179599999999998 0.031179599999999998 0.0040949999999999997"/>
              <joint name="ur5e/ur5e_0_elbow_joint" class="ur5e/size3_limited"/>
              <geom name="ur5e//unnamed_geom_12" class="ur5e/visual" material="ur5e/urblue" mesh="ur5e/forearm_0"/>
              <geom name="ur5e//unnamed_geom_13" class="ur5e/visual" material="ur5e/linkgray" mesh="ur5e/forearm_1"/>
              <geom name="ur5e//unnamed_geom_14" class="ur5e/visual" material="ur5e/black" mesh="ur5e/forearm_2"/>
              <geom name="ur5e//unnamed_geom_15" class="ur5e/visual" material="ur5e/jointgray" mesh="ur5e/forearm_3"/>
              <geom name="ur5e//unnamed_geom_16" class="ur5e/collision" size="0.055 0.059999999999999998" pos="0 0.080000000000000002 0" quat="1 1 0 0"/>
              <geom name="ur5e//unnamed_geom_17" class="ur5e/collision" size="0.037999999999999999 0.19" pos="0 0 0.20000000000000001"/>
              <body name="ur5e/ur5e_0_wrist_1_link" pos="0 0 0.39200000000000002" quat="1 0 1 0">
                <inertial pos="0 0.127 0" mass="1.2190000000000001" diaginertia="0.0025598999999999999 0.0025598999999999999 0.0021941999999999999"/>
                <joint name="ur5e/ur5e_0_wrist_1_joint" class="ur5e/size1"/>
                <geom name="ur5e//unnamed_geom_18" class="ur5e/visual" material="ur5e/black" mesh="ur5e/wrist1_0"/>
                <geom name="ur5e//unnamed_geom_19" class="ur5e/visual" material="ur5e/urblue" mesh="ur5e/wrist1_1"/>
                <geom name="ur5e//unnamed_geom_20" class="ur5e/visual" material="ur5e/jointgray" mesh="ur5e/wrist1_2"/>
                <geom name="ur5e//unnamed_geom_21" class="ur5e/collision" size="0.040000000000000001 0.070000000000000007" pos="0 0.050000000000000003 0" quat="1 1 0 0"/>
                <body name="ur5e/ur5e_0_wrist_2_link" pos="0 0.127 0">
                  <inertial pos="0 0 0.10000000000000001" mass="1.2190000000000001" diaginertia="0.0025598999999999999 0.0025598999999999999 0.0021941999999999999"/>
                  <joint name="ur5e/ur5e_0_wrist_2_joint" class="ur5e/size1" axis="0 0 1"/>
                  <geom name="ur5e//unnamed_geom_22" class="ur5e/visual" material="ur5e/black" mesh="ur5e/wrist2_0"/>
                  <geom name="ur5e//unnamed_geom_23" class="ur5e/visual" material="ur5e/urblue" mesh="ur5e/wrist2_1"/>
                  <geom name="ur5e//unnamed_geom_24" class="ur5e/visual" material="ur5e/jointgray" mesh="ur5e/wrist2_2"/>
                  <geom name="ur5e//unnamed_geom_25" class="ur5e/collision" size="0.040000000000000001 0.059999999999999998" pos="0 0 0.040000000000000001"/>
                  <geom name="ur5e//unnamed_geom_26" class="ur5e/collision" size="0.040000000000000001 0.040000000000000001" pos="0 0.02 0.10000000000000001" quat="1 1 0 0"/>
                  <body name="ur5e/ur5e_0_wrist_3_link" pos="0 0 0.10000000000000001">
                    <inertial pos="0 0.077168299999999995 0" quat="1 0 0 1" mass="0.18890000000000001" diaginertia="0.00013213400000000001 9.90863e-05 9.90863e-05"/>
                    <joint name="ur5e/ur5e_0_wrist_3_joint" class="ur5e/size1"/>
                    <geom name="ur5e//unnamed_geom_27" class="ur5e/visual" material="ur5e/linkgray" mesh="ur5e/wrist3"/>
                    <geom name="ur5e//unnamed_geom_28" class="ur5e/eef_collision" size="0.040000000000000001 0.02" pos="0 0.080000000000000002 0" quat="1 1 0 0"/>
                    <site name="ur5e/ur5e_0_attachment_site" class="ur5e/" pos="0 0.10000000000000001 0" quat="-1 1 0 0"/>
                    <body name="ur5e/ur5e_0_robotiq_gripper" pos="0 0.089999999999999997 0" quat="0 0 1 1">
                      <body name="ur5e/robotiq_base_mount" childclass="ur5e/2f85" pos="0 0 0.0070000000000000001">
                        <geom name="ur5e//unnamed_geom_29" class="ur5e/2f85_visual" material="ur5e/2f85_black" mesh="ur5e/base_mount"/>
                        <geom name="ur5e//unnamed_geom_30" class="ur5e/2f85_collision" mesh="ur5e/base_mount"/>
                        <body name="ur5e/2f85_base" pos="0 0 0.0038" quat="1 0 0 -1">
                          <inertial pos="0 -2.7039400000000001e-05 0.035467499999999999" quat="1 -0.00152849 0 0" mass="0.77744100000000005" diaginertia="0.00026028500000000002 0.000225381 0.00015270799999999999"/>
                          <geom name="ur5e//unnamed_geom_31" class="ur5e/2f85_visual" material="ur5e/2f85_black" mesh="ur5e/base"/>
                          <geom name="ur5e//unnamed_geom_32" class="ur5e/2f85_collision" mesh="ur5e/base"/>
                          <site name="ur5e/pinch" type="sphere" group="5" rgba="0.90000000000000002 0.90000000000000002 0.90000000000000002 1" size="0.0050000000000000001" pos="0 0 0.14499999999999999"/>
                          <body name="ur5e/right_driver" pos="0 0.030601099999999999 0.054904000000000001">
                            <inertial pos="2.96931e-12 0.017754700000000002 0.00107314" quat="0.68130100000000005 0.73200299999999996 0 0" mass="0.0089956299999999993" diaginertia="1.72352e-06 1.6090599999999999e-06 3.22006e-07"/>
                            <joint name="ur5e/right_driver_joint" class="ur5e/2f85_driver"/>
                            <geom name="ur5e//unnamed_geom_33" class="ur5e/2f85_visual" material="ur5e/gray" mesh="ur5e/driver"/>
                            <geom name="ur5e//unnamed_geom_34" class="ur5e/2f85_collision" mesh="ur5e/driver"/>
                            <body name="ur5e/right_coupler" pos="0 0.0315 -0.0041000000000000003">
                              <inertial pos="0 0.0030120899999999998 0.023217499999999999" quat="0.70563600000000004 -0.045590400000000003 0.045590400000000003 0.70563600000000004" mass="0.0140974" diaginertia="4.1620600000000001e-06 3.5221600000000001e-06 8.8813100000000003e-07"/>
                              <joint name="ur5e/right_coupler_joint" class="ur5e/2f85_coupler"/>
                              <geom name="ur5e//unnamed_geom_35" class="ur5e/2f85_visual" material="ur5e/2f85_black" mesh="ur5e/coupler"/>
                              <geom name="ur5e/robotiq_collision" class="ur5e/2f85_collision" mesh="ur5e/coupler"/>
                            </body>
                          </body>
                          <body name="ur5e/right_spring_link" pos="0 0.0132 0.060900000000000003">
                            <inertial pos="-8.6500500000000008e-09 0.018162399999999999 0.021265800000000001" quat="0.66340299999999996 -0.24473700000000001 0.24473700000000001 0.66340299999999996" mass="0.022164199999999998" diaginertia="8.9685299999999993e-06 6.7173299999999996e-06 2.6393100000000001e-06"/>
                            <joint name="ur5e/right_spring_link_joint" class="ur5e/2f85_spring_link"/>
                            <geom name="ur5e//unnamed_geom_37" class="ur5e/2f85_visual" material="ur5e/2f85_black" mesh="ur5e/spring_link"/>
                            <geom name="ur5e//unnamed_geom_38" class="ur5e/2f85_collision" mesh="ur5e/spring_link"/>
                            <body name="ur5e/right_follower" pos="0 0.055 0.037499999999999999">
                              <inertial pos="0 -0.011046 0.012478599999999999" quat="1 0.16639999999999999 0 0" mass="0.012522200000000001" diaginertia="2.6741500000000001e-06 2.4559000000000001e-06 6.0203100000000003e-07"/>
                              <joint name="ur5e/right_follower_joint" class="ur5e/2f85_follower"/>
                              <geom name="ur5e//unnamed_geom_39" class="ur5e/2f85_visual" material="ur5e/2f85_black" mesh="ur5e/follower"/>
                              <geom name="ur5e//unnamed_geom_40" class="ur5e/2f85_collision" mesh="ur5e/follower"/>
                              <body name="ur5e/right_pad" pos="0 -0.0189 0.013520000000000001">
                                <geom name="ur5e/right_pad1" class="ur5e/2f85_pad_box1"/>
                                <geom name="ur5e/right_pad2" class="ur5e/2f85_pad_box2"/>
                                <inertial pos="0 -0.0025000000000000001 0.018499999999999999" quat="0.70710700000000004 0 0 0.70710700000000004" mass="0.0035000000000000001" diaginertia="4.7395799999999999e-07 3.6458299999999998e-07 1.23958e-07"/>
                                <geom name="ur5e//unnamed_geom_43" class="ur5e/2f85_visual" mesh="ur5e/pad"/>
                                <body name="ur5e/right_silicone_pad">
                                  <geom name="ur5e//unnamed_geom_44" class="ur5e/2f85_visual" material="ur5e/2f85_black" mesh="ur5e/silicone_pad"/>
                                </body>
                              </body>
                            </body>
                          </body>
                          <site name="ur5e/robotiq_ee" type="cylinder" group="3" rgba="1 0 0 1" size="0.02" pos="0 0 0.12" zaxis="0 0 -1"/>
                          <body name="ur5e/robotiq_tip" pos="0 0 0.12" zaxis="0 0 -1"/>
                          <body name="ur5e/left_driver" pos="0 -0.030601099999999999 0.054904000000000001" quat="0 0 0 1">
                            <inertial pos="0 0.017754700000000002 0.00107314" quat="0.68130100000000005 0.73200299999999996 0 0" mass="0.0089956299999999993" diaginertia="1.72352e-06 1.6090599999999999e-06 3.22006e-07"/>
                            <joint name="ur5e/left_driver_joint" class="ur5e/2f85_driver"/>
                            <geom name="ur5e//unnamed_geom_45" class="ur5e/2f85_visual" material="ur5e/gray" mesh="ur5e/driver"/>
                            <geom name="ur5e//unnamed_geom_46" class="ur5e/2f85_collision" mesh="ur5e/driver"/>
                            <body name="ur5e/left_coupler" pos="0 0.0315 -0.0041000000000000003">
                              <inertial pos="0 0.0030120899999999998 0.023217499999999999" quat="0.70563600000000004 -0.045590400000000003 0.045590400000000003 0.70563600000000004" mass="0.0140974" diaginertia="4.1620600000000001e-06 3.5221600000000001e-06 8.8813100000000003e-07"/>
                              <joint name="ur5e/left_coupler_joint" class="ur5e/2f85_coupler"/>
                              <geom name="ur5e//unnamed_geom_47" class="ur5e/2f85_visual" material="ur5e/2f85_black" mesh="ur5e/coupler"/>
                              <geom name="ur5e//unnamed_geom_48" class="ur5e/2f85_collision" mesh="ur5e/coupler"/>
                            </body>
                          </body>
                          <body name="ur5e/left_spring_link" pos="0 -0.0132 0.060900000000000003" quat="0 0 0 1">
                            <inertial pos="-8.6500500000000008e-09 0.018162399999999999 0.021265800000000001" quat="0.66340299999999996 -0.24473700000000001 0.24473700000000001 0.66340299999999996" mass="0.022164199999999998" diaginertia="8.9685299999999993e-06 6.7173299999999996e-06 2.6393100000000001e-06"/>
                            <joint name="ur5e/left_spring_link_joint" class="ur5e/2f85_spring_link"/>
                            <geom name="ur5e//unnamed_geom_49" class="ur5e/2f85_visual" material="ur5e/2f85_black" mesh="ur5e/spring_link"/>
                            <geom name="ur5e//unnamed_geom_50" class="ur5e/2f85_collision" mesh="ur5e/spring_link"/>
                            <body name="ur5e/left_follower" pos="0 0.055 0.037499999999999999">
                              <inertial pos="0 -0.011046 0.012478599999999999" quat="1 0.16639999999999999 0 0" mass="0.012522200000000001" diaginertia="2.6741500000000001e-06 2.4559000000000001e-06 6.0203100000000003e-07"/>
                              <joint name="ur5e/left_follower_joint" class="ur5e/2f85_follower"/>
                              <geom name="ur5e//unnamed_geom_51" class="ur5e/2f85_visual" material="ur5e/2f85_black" mesh="ur5e/follower"/>
                              <geom name="ur5e//unnamed_geom_52" class="ur5e/2f85_collision" mesh="ur5e/follower"/>
                              <body name="ur5e/left_pad" pos="0 -0.0189 0.013520000000000001">
                                <geom name="ur5e/left_pad1" class="ur5e/2f85_pad_box1"/>
                                <geom name="ur5e/left_pad2" class="ur5e/2f85_pad_box2"/>
                                <inertial pos="0 -0.0025000000000000001 0.018499999999999999" quat="1 0 0 1" mass="0.0035000000000000001" diaginertia="4.7395799999999999e-07 3.6458299999999998e-07 1.23958e-07"/>
                                <geom name="ur5e//unnamed_geom_55" class="ur5e/2f85_visual" mesh="ur5e/pad"/>
                                <body name="ur5e/left_silicone_pad">
                                  <geom name="ur5e//unnamed_geom_56" class="ur5e/2f85_visual" material="ur5e/2f85_black" mesh="ur5e/silicone_pad"/>
                                </body>
                              </body>
                            </body>
                          </body>
                        </body>
                      </body>
                      <site name="ur5e/ur5e_0_disk_site" class="ur5e/" type="sphere" rgba="0.5 0.5 0.5 0.29999999999999999" size="0.01" pos="0 0 0.20000000000000001"/>
                    </body>
                  </body>
                </body>
              </body>
            </body>
          </body>
        </body>
      </body>
    </body>
    <site name="panda2" class="/" size="0.001 0.001 0.001" pos="0.40000000000000002 -0.14999999999999999 0.10000000000000001"/>
    <body pos="0.40000000000000002 -0.14999999999999999 0.10000000000000001" name="panda2/">
      <light name="panda2/top" class="panda2/" mode="trackcom" pos="0 0 2"/>
      <body name="panda2/link0" childclass="panda2/panda">
        <joint name="panda2/panda_base_joint" type="slide" axis="1 0 0" range="-1.5 1.3" armature="1" damping="1000"/>
        <inertial pos="-0.041017999999999999 -0.00013999999999999999 0.049973999999999998" mass="0.62976900000000002" fullinertia="0.00315 0.0038800000000000002 0.0042849999999999997 8.2903999999999996e-07 0.00014999999999999999 8.2299000000000006e-06"/>
        <geom name="panda2//unnamed_geom_0" class="panda2/visual" material="panda2/off_white" mesh="panda2/link0_0"/>
        <geom name="panda2//unnamed_geom_1" class="panda2/visual" material="panda2/black" mesh="panda2/link0_1"/>
        <geom name="panda2//unnamed_geom_2" class="panda2/visual" material="panda2/off_white" mesh="panda2/link0_2"/>
        <geom name="panda2//unnamed_geom_3" class="panda2/visual" material="panda2/black" mesh="panda2/link0_3"/>
        <geom name="panda2//unnamed_geom_4" class="panda2/visual" material="panda2/off_white" mesh="panda2/link0_4"/>
        <geom name="panda2//unnamed_geom_5" class="panda2/visual" material="panda2/black" mesh="panda2/link0_5"/>
        <geom name="panda2//unnamed_geom_6" class="panda2/visual" material="panda2/white" mesh="panda2/link0_7"/>
        <geom name="panda2//unnamed_geom_7" class="panda2/visual" material="panda2/white" mesh="panda2/link0_8"/>
        <geom name="panda2//unnamed_geom_8" class="panda2/visual" material="panda2/black" mesh="panda2/link0_9"/>
        <geom name="panda2//unnamed_geom_9" class="panda2/visual" material="panda2/off_white" mesh="panda2/link0_10"/>
        <geom name="panda2//unnamed_geom_10" class="panda2/visual" material="panda2/white" mesh="panda2/link0_11"/>
        <geom name="panda2//unnamed_geom_11" class="panda2/collision" mesh="panda2/link0_c"/>
        <body name="panda2/link1" pos="0 0 0.33300000000000002">
          <inertial pos="0.003875 0.002081 -0.047620000000000003" mass="4.9706840000000003" fullinertia="0.70337000000000005 0.70660999999999996 0.0091170000000000001 -0.00013899999999999999 0.0067720000000000002 0.019168999999999999"/>
          <joint name="panda2/joint1"/>
          <geom name="panda2//unnamed_geom_12" class="panda2/visual" material="panda2/white" mesh="panda2/link1"/>
          <geom name="panda2//unnamed_geom_13" class="panda2/collision" mesh="panda2/link1_c"/>
          <body name="panda2/link2" quat="1 -1 0 0">
            <inertial pos="-0.0031410000000000001 -0.028719999999999999 0.0034949999999999998" mass="0.646926" fullinertia="0.0079620000000000003 0.02811 0.025995000000000001 -0.0039249999999999997 0.010253999999999999 0.00070399999999999998"/>
            <joint name="panda2/joint2" range="-1.7627999999999999 1.7627999999999999"/>
            <geom name="panda2//unnamed_geom_14" class="panda2/visual" material="panda2/white" mesh="panda2/link2"/>
            <geom name="panda2//unnamed_geom_15" class="panda2/collision" mesh="panda2/link2_c"/>
            <body name="panda2/link3" pos="0 -0.316 0" quat="1 1 0 0">
              <joint name="panda2/joint3"/>
              <inertial pos="0.027518000000000001 0.039252000000000002 -0.066502000000000006" mass="3.2286039999999998" fullinertia="0.037241999999999997 0.036155 0.010829999999999999 -0.0047609999999999996 -0.011396 -0.012805"/>
              <geom name="panda2//unnamed_geom_16" class="panda2/visual" material="panda2/white" mesh="panda2/link3_0"/>
              <geom name="panda2//unnamed_geom_17" class="panda2/visual" material="panda2/white" mesh="panda2/link3_1"/>
              <geom name="panda2//unnamed_geom_18" class="panda2/visual" material="panda2/white" mesh="panda2/link3_2"/>
              <geom name="panda2//unnamed_geom_19" class="panda2/visual" material="panda2/black" mesh="panda2/link3_3"/>
              <geom name="panda2//unnamed_geom_20" class="panda2/collision" mesh="panda2/link3_c"/>
              <body name="panda2/link4" pos="0.082500000000000004 0 0" quat="1 1 0 0">
                <inertial pos="-0.053170000000000002 0.104419 0.027453999999999999" mass="3.5878950000000001" fullinertia="0.025853000000000001 0.019552 0.028323000000000001 0.007796 -0.0013320000000000001 0.0086409999999999994"/>
                <joint name="panda2/joint4" range="-3.0718000000000001 -0.069800000000000001"/>
                <geom name="panda2//unnamed_geom_21" class="panda2/visual" material="panda2/white" mesh="panda2/link4_0"/>
                <geom name="panda2//unnamed_geom_22" class="panda2/visual" material="panda2/white" mesh="panda2/link4_1"/>
                <geom name="panda2//unnamed_geom_23" class="panda2/visual" material="panda2/black" mesh="panda2/link4_2"/>
                <geom name="panda2//unnamed_geom_24" class="panda2/visual" material="panda2/white" mesh="panda2/link4_3"/>
                <geom name="panda2//unnamed_geom_25" class="panda2/collision" mesh="panda2/link4_c"/>
                <body name="panda2/link5" pos="-0.082500000000000004 0.38400000000000001 0" quat="1 -1 0 0">
                  <inertial pos="-0.011953 0.041064999999999997 -0.038436999999999999" mass="1.225946" fullinertia="0.035548999999999997 0.029474 0.0086269999999999993 -0.002117 -0.0040369999999999998 0.00022900000000000001"/>
                  <joint name="panda2/joint5"/>
                  <geom name="panda2//unnamed_geom_26" class="panda2/visual" material="panda2/black" mesh="panda2/link5_0"/>
                  <geom name="panda2//unnamed_geom_27" class="panda2/visual" material="panda2/white" mesh="panda2/link5_1"/>
                  <geom name="panda2//unnamed_geom_28" class="panda2/visual" material="panda2/white" mesh="panda2/link5_2"/>
                  <geom name="panda2//unnamed_geom_29" class="panda2/collision" mesh="panda2/link5_c0"/>
                  <geom name="panda2//unnamed_geom_30" class="panda2/collision" mesh="panda2/link5_c1"/>
                  <geom name="panda2//unnamed_geom_31" class="panda2/collision" mesh="panda2/link5_c2"/>
                  <body name="panda2/link6" quat="1 1 0 0">
                    <inertial pos="0.060149000000000001 -0.014116999999999999 -0.010517" mass="1.666555" fullinertia="0.001964 0.0043540000000000002 0.0054330000000000003 0.00010900000000000001 -0.001158 0.00034099999999999999"/>
                    <joint name="panda2/joint6" range="-0.017500000000000002 3.7524999999999999"/>
                    <geom name="panda2//unnamed_geom_32" class="panda2/visual" material="panda2/off_white" mesh="panda2/link6_0"/>
                    <geom name="panda2//unnamed_geom_33" class="panda2/visual" material="panda2/white" mesh="panda2/link6_1"/>
                    <geom name="panda2//unnamed_geom_34" class="panda2/visual" material="panda2/black" mesh="panda2/link6_2"/>
                    <geom name="panda2//unnamed_geom_35" class="panda2/visual" material="panda2/white" mesh="panda2/link6_3"/>
                    <geom name="panda2//unnamed_geom_36" class="panda2/visual" material="panda2/white" mesh="panda2/link6_4"/>
                    <geom name="panda2//unnamed_geom_37" class="panda2/visual" material="panda2/white" mesh="panda2/link6_5"/>
                    <geom name="panda2//unnamed_geom_38" class="panda2/visual" material="panda2/white" mesh="panda2/link6_6"/>
                    <geom name="panda2//unnamed_geom_39" class="panda2/visual" material="panda2/light_blue" mesh="panda2/link6_7"/>
                    <geom name="panda2//unnamed_geom_40" class="panda2/visual" material="panda2/light_blue" mesh="panda2/link6_8"/>
                    <geom name="panda2//unnamed_geom_41" class="panda2/visual" material="panda2/black" mesh="panda2/link6_9"/>
                    <geom name="panda2//unnamed_geom_42" class="panda2/visual" material="panda2/black" mesh="panda2/link6_10"/>
                    <geom name="panda2//unnamed_geom_43" class="panda2/visual" material="panda2/white" mesh="panda2/link6_11"/>
                    <geom name="panda2//unnamed_geom_44" class="panda2/visual" material="panda2/green" mesh="panda2/link6_12"/>
                    <geom name="panda2//unnamed_geom_45" class="panda2/visual" material="panda2/white" mesh="panda2/link6_13"/>
                    <geom name="panda2//unnamed_geom_46" class="panda2/visual" material="panda2/black" mesh="panda2/link6_14"/>
                    <geom name="panda2//unnamed_geom_47" class="panda2/visual" material="panda2/black" mesh="panda2/link6_15"/>
                    <geom name="panda2//unnamed_geom_48" class="panda2/visual" material="panda2/white" mesh="panda2/link6_16"/>
                    <geom name="panda2//unnamed_geom_49" class="panda2/collision" mesh="panda2/link6_c"/>
                    <body name="panda2/link7" pos="0.087999999999999995 0 0" quat="1 1 0 0">
                      <inertial pos="0.010517 -0.0042519999999999997 0.061596999999999999" mass="0.73552200000000001" fullinertia="0.012515999999999999 0.010026999999999999 0.0048149999999999998 -0.000428 -0.001196 -0.00074100000000000001"/>
                      <joint name="panda2/joint7"/>
                      <geom name="panda2//unnamed_geom_50" class="panda2/visual" material="panda2/white" mesh="panda2/link7_0"/>
                      <geom name="panda2//unnamed_geom_51" class="panda2/visual" material="panda2/black" mesh="panda2/link7_1"/>
                      <geom name="panda2//unnamed_geom_52" class="panda2/visual" material="panda2/black" mesh="panda2/link7_2"/>
                      <geom name="panda2//unnamed_geom_53" class="panda2/visual" material="panda2/black" mesh="panda2/link7_3"/>
                      <geom name="panda2//unnamed_geom_54" class="panda2/visual" material="panda2/black" mesh="panda2/link7_4"/>
                      <geom name="panda2//unnamed_geom_55" class="panda2/visual" material="panda2/black" mesh="panda2/link7_5"/>
                      <geom name="panda2//unnamed_geom_56" class="panda2/visual" material="panda2/black" mesh="panda2/link7_6"/>
                      <geom name="panda2//unnamed_geom_57" class="panda2/visual" material="panda2/white" mesh="panda2/link7_7"/>
                      <geom name="panda2//unnamed_geom_58" class="panda2/collision" mesh="panda2/link7_c"/>
                      <body name="panda2/hand" pos="0 0 0.107" quat="0.92387949999999996 0 0 -0.38268340000000001">
                        <body name="panda2/panda_palm" pos="0 0 0.059999999999999998" zaxis="0 0 -1"/>
                        <site name="panda2/ee" type="sphere"/>
                        <inertial pos="-0.01 0 0.029999999999999999" mass="0.72999999999999998" diaginertia="0.001 0.0025000000000000001 0.0016999999999999999"/>
                        <geom name="panda2//unnamed_geom_59" class="panda2/visual" material="panda2/off_white" mesh="panda2/hand_0"/>
                        <geom name="panda2//unnamed_geom_60" class="panda2/visual" material="panda2/black" mesh="panda2/hand_1"/>
                        <geom name="panda2//unnamed_geom_61" class="panda2/visual" material="panda2/black" mesh="panda2/hand_2"/>
                        <geom name="panda2//unnamed_geom_62" class="panda2/visual" material="panda2/white" mesh="panda2/hand_3"/>
                        <geom name="panda2//unnamed_geom_63" class="panda2/visual" material="panda2/off_white" mesh="panda2/hand_4"/>
                        <geom name="panda2/panda_hand_collision" class="panda2/collision" mesh="panda2/hand_c"/>
                        <body name="panda2/left_finger" pos="0 0 0.058400000000000001">
                          <inertial pos="0 0 0" mass="0.014999999999999999" diaginertia="2.3750000000000001e-06 2.3750000000000001e-06 7.5000000000000002e-07"/>
                          <joint name="panda2/finger_joint1" class="panda2/finger"/>
                          <geom name="panda2//unnamed_geom_65" class="panda2/visual" material="panda2/off_white" mesh="panda2/finger_0"/>
                          <geom name="panda2//unnamed_geom_66" class="panda2/visual" material="panda2/black" mesh="panda2/finger_1"/>
                          <geom name="panda2//unnamed_geom_67" class="panda2/collision" mesh="panda2/finger_0"/>
                          <geom name="panda2//unnamed_geom_68" class="panda2/fingertip_pad_collision_1"/>
                          <geom name="panda2//unnamed_geom_69" class="panda2/fingertip_pad_collision_2"/>
                          <geom name="panda2//unnamed_geom_70" class="panda2/fingertip_pad_collision_3"/>
                          <geom name="panda2//unnamed_geom_71" class="panda2/fingertip_pad_collision_4"/>
                          <geom name="panda2//unnamed_geom_72" class="panda2/fingertip_pad_collision_5"/>
                        </body>
                        <body name="panda2/right_finger" pos="0 0 0.058400000000000001" quat="0 0 0 1">
                          <inertial pos="0 0 0" mass="0.014999999999999999" diaginertia="2.3750000000000001e-06 2.3750000000000001e-06 7.5000000000000002e-07"/>
                          <joint name="panda2/finger_joint2" class="panda2/finger"/>
                          <geom name="panda2//unnamed_geom_73" class="panda2/visual" material="panda2/off_white" mesh="panda2/finger_0"/>
                          <geom name="panda2//unnamed_geom_74" class="panda2/visual" material="panda2/black" mesh="panda2/finger_1"/>
                          <geom name="panda2//unnamed_geom_75" class="panda2/collision" mesh="panda2/finger_0"/>
                          <geom name="panda2//unnamed_geom_76" class="panda2/fingertip_pad_collision_1"/>
                          <geom name="panda2//unnamed_geom_77" class="panda2/fingertip_pad_collision_2"/>
                          <geom name="panda2//unnamed_geom_78" class="panda2/fingertip_pad_collision_3"/>
                          <geom name="panda2//unnamed_geom_79" class="panda2/fingertip_pad_collision_4"/>
                          <geom name="panda2//unnamed_geom_80" class="panda2/fingertip_pad_collision_5"/>
                        </body>
                      </body>
                    </body>
                  </body>
                </body>
              </body>
            </body>
          </body>
        </body>
      </body>
    </body>
    <camera name="face_panda1" class="/" mode="fixed" pos="0.062 -2.806 0.76800000000000002" xyaxes="1 0.0089999999999999993 -0 0.001 -0.13100000000000001 0.99099999999999999"/>
    <camera name="face_panda2" class="/" mode="fixed" pos="0.084000000000000005 3.7109999999999999 0.77200000000000002" xyaxes="-1 0.016 0 0.002 0.111 0.99399999999999999"/>
    <camera name="top_cam" class="/" mode="fixed" pos="-0.001 0.65200000000000002 2.0569999999999999" xyaxes="-1 -0 -0 0 -1 0.019"/>
    <camera name="right_cam" class="/" mode="fixed" pos="1.873 0.60499999999999998 0.92600000000000005" xyaxes="0.014 1 0 -0.24199999999999999 0.0030000000000000001 0.96999999999999997"/>
    <camera name="left_cam" class="/" mode="fixed" pos="-1.873 0.60499999999999998 0.92600000000000005" xyaxes="-0 -1 0 0.17699999999999999 -0 0.98399999999999999"/>
    <camera name="teaser" class="/" pos="2.6749999999999998 -0.747 1.9970000000000001" xyaxes="0.496 0.86899999999999999 -0 -0.42899999999999999 0.245 0.86899999999999999"/>
    <camera name="video" class="/" pos="1.9570000000000001 -0.28100000000000003 1.7310000000000001" xyaxes="0.48699999999999999 0.874 0 -0.5 0.27800000000000002 0.81999999999999995"/>
  </worldbody>
  <contact>
    <exclude name="ur5e//unnamed_contact_0" body1="ur5e/2f85_base" body2="ur5e/left_driver"/>
    <exclude name="ur5e//unnamed_contact_1" body1="ur5e/2f85_base" body2="ur5e/right_driver"/>
    <exclude name="ur5e//unnamed_contact_2" body1="ur5e/2f85_base" body2="ur5e/left_spring_link"/>
    <exclude name="ur5e//unnamed_contact_3" body1="ur5e/2f85_base" body2="ur5e/right_spring_link"/>
    <exclude name="ur5e//unnamed_contact_4" body1="ur5e/right_coupler" body2="ur5e/right_follower"/>
    <exclude name="ur5e//unnamed_contact_5" body1="ur5e/left_coupler" body2="ur5e/left_follower"/>
  </contact>
  <equality>
    <weld name="door_handle_panda" class="/" active="false" body1="cabinet/right_door_handle" body2="ur5e/robotiq_tip" relpose="0 0 0 1 0 0 0"/>
    <weld name="keycard_panda" class="/" active="false" body1="keycard" body2="panda2/panda_palm" relpose="0 0 0 1 0 0 0"/>
    <connect name="ur5e//unnamed_equality_0" class="ur5e/" solref="0.0050000000000000001 1" solimp="0.94999999999999996 0.98999999999999999 0.001" body1="ur5e/right_follower" body2="ur5e/right_coupler" anchor="0 0 0"/>
    <connect name="ur5e//unnamed_equality_1" class="ur5e/" solref="0.0050000000000000001 1" solimp="0.94999999999999996 0.98999999999999999 0.001" body1="ur5e/left_follower" body2="ur5e/left_coupler" anchor="0 0 0"/>
    <joint name="ur5e//unnamed_equality_2" class="ur5e/" solref="0.0050000000000000001 1" solimp="0.94999999999999996 0.98999999999999999 0.001" joint1="ur5e/right_driver_joint" joint2="ur5e/left_driver_joint" polycoef="0 1 0 0 0"/>
    <joint name="panda2//unnamed_equality_0" class="panda2/" solref="0.0050000000000000001 1" solimp="0.94999999999999996 0.98999999999999999 0.001" joint1="panda2/finger_joint1" joint2="panda2/finger_joint2"/>
  </equality>
  <tendon>
    <fixed name="ur5e/2f85_split" class="ur5e/">
      <joint joint="ur5e/right_driver_joint" coef="0.5"/>
      <joint joint="ur5e/left_driver_joint" coef="0.5"/>
    </fixed>
    <fixed name="panda2/split" class="panda2/">
      <joint joint="panda2/finger_joint1" coef="0.5"/>
      <joint joint="panda2/finger_joint2" coef="0.5"/>
    </fixed>
  </tendon>
  <actuator>
    <position name="ur5e/ur5e_0_base" class="ur5e/" ctrlrange="-1.5 1.3" joint="ur5e/ur5e_0_base_joint" kp="1000"/>
    <position name="ur5e/ur5e_0_shoulder_pan" class="ur5e/size3" joint="ur5e/ur5e_0_shoulder_pan_joint"/>
    <position name="ur5e/ur5e_0_shoulder_lift" class="ur5e/size3" joint="ur5e/ur5e_0_shoulder_lift_joint"/>
    <position name="ur5e/ur5e_0_elbow" class="ur5e/size3_limited" joint="ur5e/ur5e_0_elbow_joint"/>
    <position name="ur5e/ur5e_0_wrist_1" class="ur5e/size1" joint="ur5e/ur5e_0_wrist_1_joint"/>
    <position name="ur5e/ur5e_0_wrist_2" class="ur5e/size1" joint="ur5e/ur5e_0_wrist_2_joint"/>
    <position name="ur5e/ur5e_0_wrist_3" class="ur5e/size1" joint="ur5e/ur5e_0_wrist_3_joint"/>
    <general name="ur5e/robotiq_fingers_actuator" class="ur5e/2f85" ctrlrange="0 255" forcerange="-5 5" tendon="ur5e/2f85_split" gainprm="0.31372549999999999 0 0" biasprm="0 -100 -10"/>
    <position name="panda2/panda_base" class="panda2/" ctrlrange="-1.5 1.3" joint="panda2/panda_base_joint" kp="2000"/>
    <general name="panda2/actuator1" class="panda2/panda" joint="panda2/joint1" gainprm="4500" biasprm="0 -4500 -450"/>
    <general name="panda2/actuator2" class="panda2/panda" ctrlrange="-1.7627999999999999 1.7627999999999999" joint="panda2/joint2" gainprm="4500" biasprm="0 -4500 -450"/>
    <general name="panda2/actuator3" class="panda2/panda" joint="panda2/joint3" gainprm="3500" biasprm="0 -3500 -350"/>
    <general name="panda2/actuator4" class="panda2/panda" ctrlrange="-3.0718000000000001 -0.069800000000000001" joint="panda2/joint4" gainprm="3500" biasprm="0 -3500 -350"/>
    <general name="panda2/actuator5" class="panda2/panda" forcerange="-12 12" joint="panda2/joint5" gainprm="2000" biasprm="0 -2000 -200"/>
    <general name="panda2/actuator6" class="panda2/panda" ctrlrange="-0.017500000000000002 3.7524999999999999" forcerange="-12 12" joint="panda2/joint6" gainprm="2000" biasprm="0 -2000 -200"/>
    <general name="panda2/actuator7" class="panda2/panda" forcerange="-12 12" joint="panda2/joint7" gainprm="2000" biasprm="0 -2000 -200"/>
    <general name="panda2/panda_gripper_actuator" class="panda2/panda" ctrlrange="0 255" forcerange="-100 100" tendon="panda2/split" gainprm="0.015686274510000001 0 0" biasprm="0 -100 -10"/>
  </actuator>
</mujoco>
